Workbook

Sheet Data_Dictionary
A1: SkyBridge Airways - Daily Flight Log (1 Jan to 30 Apr 2026, 120 days)
A2: One flagship departure from Delhi recorded per day. Aircraft capacity = 180 seats. Customer rating scale = 1 to 5.
A4: Variable | B4: Type | C4: Meaning | D4: Unit / Valid range
A5: Date | B5: Date (time series) | C5: Day of departure | D5: Daily, 1 Jan - 30 Apr 2026
A6: Flight_ID | B6: Text (ID) | C6: Unique flight code | D6: SB-001 to SB-120
A7: Route | B7: Category | C7: Destination sector from Delhi | D7: Mumbai / Bengaluru / Goa
A8: Passengers | B8: Numeric | C8: Passengers who flew | D8: Count, 0 to 180
A9: Ticket_Price | B9: Numeric | C9: Average fare paid per passenger | D9: INR
A10: Delay_Minutes | B10: Numeric | C10: Departure delay | D10: Minutes, 0 or more
A11: Flight_Duration_Min | B11: Numeric | C11: Gate-to-gate flying time | D11: Minutes
A12: Fuel_Cost | B12: Numeric | C12: Fuel cost for the flight | D12: INR thousand
A13: Ancillary_Revenue | B13: Numeric | C13: Bags, meals, seat selection revenue | D13: INR
A14: Baggage_Complaints | B14: Numeric (count) | C14: Baggage complaints logged for the flight | D14: Count
A15: Customer_Rating | B15: Numeric | C15: Average passenger satisfaction | D15: Scale 1 to 5
A16: Crew_Overtime_Hours | B16: Numeric | C16: Total crew overtime for the flight | D16: Hours
A18: Sheets: Unclean_Data (raw data with blanks and unusual values) | Excel_Stats (Excel formulas on the raw data). Cleaning is done in the Python (Colab) notebook.
A19: In Unclean_Data, red-shaded cells are blank (missing) values.

Sheet Unclean_Data
A1: Date | B1: Flight_ID | C1: Route | D1: Passengers | E1: Ticket_Price | F1: Delay_Minutes | G1: Flight_Duration_Min | H1: Fuel_Cost | I1: Ancillary_Revenue | J1: Baggage_Complaints | K1: Customer_Rating | L1: Crew_Overtime_Hours
A2: 46023 | B2: SB-001 | C2: Delhi-Mumbai | D2: 143 | E2: 5650 | F2: 26 | G2: 133 | H2: 429 | I2: 60600 | J2: 2 | K2: 3.9
A3: 46024 | B3: SB-002 | C3: Delhi-Bengaluru | D3: 158 | E3: 7200 | F3: 18 | G3: 163 | H3: 528 | I3: 67600 | J3: 3 | K3: 4.1 | L3: 6.3
A4: 46025 | B4: SB-003 | C4: Delhi-Bengaluru | D4: 178 | E4: 6200 | F4: 6 | G4: 169 | H4: 585 | I4: 71700 | J4: 3 | K4: 4.4 | L4: 5.3
A5: 46026 | B5: SB-004 | C5: Delhi-Mumbai | D5: 145 | E5: 5800 | F5: 9 | G5: 131 | H5: 433 | I5: 61400 | J5: 4 | K5: 4.1 | L5: 4
A6: 46027 | B6: SB-005 | C6: Delhi-Mumbai | D6: 159 | E6: 5450 | F6: 18 | G6: 130 | H6: 428 | I6: 70000 | J6: 2 | K6: 4 | L6: 8.7
A7: 46028 | B7: SB-006 | C7: Delhi-Goa | D7: 161 | E7: 5950 | F7: 9 | G7: 173 | H7: 568 | I7: 63300 | J7: 5 | K7: 4 | L7: 4.8
A8: 46029 | B8: SB-007 | C8: Delhi-Goa | D8: 156 | E8: 6450 | F8: 22 | G8: 166 | H8: 554 | I8: 51600 | J8: 2 | K8: 4.4
A9: 46030 | B9: SB-008 | C9: Delhi-Mumbai | D9: 163 | E9: 5950 | F9: 8 | H9: 422 | I9: 67700 | J9: 0 | K9: 4 | L9: 7.4
A10: 46031 | B10: SB-009 | C10: Delhi-Bengaluru | D10: 152 | E10: 6900 | F10: 10 | G10: 165 | H10: 545 | I10: 52500 | J10: 4 | K10: 4.4 | L10: 5.5
A11: 46032 | B11: SB-010 | C11: Delhi-Mumbai | D11: 150 | E11: 5800 | G11: 129 | H11: 441 | I11: 66800 | J11: 4 | K11: 3.6 | L11: 8.6
A12: 46033 | B12: SB-011 | C12: Delhi-Goa | D12: 170 | E12: 5950 | F12: 15 | G12: 162 | H12: 530 | J12: 5 | K12: 3.6 | L12: 6.1
A13: 46034 | B13: SB-012 | C13: Delhi-Goa | D13: 159 | E13: 5450 | F13: 28 | G13: 174 | H13: 541 | I13: 57500 | J13: 3 | K13: 3.9 | L13: 6.4
A14: 46035 | B14: SB-013 | C14: Delhi-Bengaluru | D14: 167 | E14: 6300 | F14: 28 | G14: 168 | H14: 545 | I14: 57000 | J14: 2 | K14: 4.1 | L14: 7.3
A15: 46036 | B15: SB-014 | C15: Delhi-Goa | D15: 153 | E15: 5800 | F15: 6 | G15: 165 | H15: 555 | J15: 4 | K15: 4.5 | L15: 6.3
A16: 46037 | B16: SB-015 | C16: Delhi-Bengaluru | D16: 169 | E16: 57000 | F16: 15 | H16: 593 | I16: 63800 | J16: 3 | L16: 6.4
A17: 46038 | B17: SB-016 | C17: Delhi-Goa | D17: 155 | E17: 6250 | F17: 19 | G17: 168 | H17: 559 | I17: 65900 | J17: 7 | K17: 4.2 | L17: 7.9
A18: 46039 | B18: SB-017 | C18: Delhi-Bengaluru | D18: 145 | E18: 6700 | F18: 12 | G18: 164 | H18: 561 | I18: 48800 | J18: 2 | K18: 3.6 | L18: 4.8
A19: 46040 | B19: SB-018 | C19: Delhi-Mumbai | D19: 134 | E19: 5900 | F19: 23 | G19: 133 | H19: 424 | I19: 55100 | J19: 3 | K19: 4.2 | L19: 7.2
A20: 46041 | B20: SB-019 | C20: Delhi-Mumbai | D20: 137 | E20: 5150 | F20: 1 | G20: 133 | H20: 457 | J20: 1 | K20: 3.9 | L20: 6.4
A21: 46042 | B21: SB-020 | C21: Delhi-Mumbai | D21: 160 | E21: 5100 | F21: 39 | G21: 129 | H21: 429 | I21: 67600 | J21: 0 | K21: 3.8 | L21: 4.2
A22: 46043 | B22: SB-021 | C22: Delhi-Bengaluru | D22: 132 | E22: 6100 | F22: 26 | G22: 172 | H22: 577 | I22: 49900 | J22: 1 | K22: 4.5 | L22: 8.1
A23: 46044 | B23: SB-022 | C23: Delhi-Bengaluru | D23: 145 | E23: 6150 | F23: 10 | G23: 170 | H23: 521 | I23: 56100 | J23: 3 | K23: 4.4
A24: 46045 | B24: SB-023 | C24: Delhi-Bengaluru | D24: 180 | E24: 6250 | F24: -45 | G24: 164 | I24: 67700 | J24: 1 | K24: 4 | L24: 8.4
A25: 46046 | B25: SB-024 | D25: 168 | E25: 5850 | F25: 5 | G25: 128 | H25: 426 | I25: 69300 | J25: 2 | L25: 5.4
A26: 46047 | B26: SB-025 | C26: Delhi-Bengaluru | D26: 179 | E26: 7250 | F26: 24 | G26: 170 | H26: 588 | I26: 70300 | J26: 4 | K26: 4.3 | L26: 4.8
A27: 46048 | B27: SB-026 | C27: Delhi-Mumbai | D27: 138 | E27: 5450 | F27: 20 | G27: 128 | H27: 425 | I27: 60600 | J27: 2 | K27: 4.1
A28: 46049 | B28: SB-027 | C28: Delhi-Mumbai | D28: 120 | F28: 44 | G28: 132 | H28: 422 | I28: 38100 | J28: 2 | K28: 3.9 | L28: 5.2
A29: 46050 | B29: SB-028 | C29: Delhi-Bengaluru | D29: 168 | E29: 6150 | F29: 6 | G29: 174 | H29: 563 | I29: 58500 | J29: 6 | K29: 4 | L29: 4.9
A30: 46051 | B30: SB-029 | C30: Delhi-Bengaluru | D30: 133 | E30: 5550 | F30: 14 | G30: 171 | H30: 570 | I30: 44300 | J30: 2 | K30: 4.3 | L30: 7.1
A31: 46052 | B31: SB-030 | C31: Delhi-Mumbai | D31: 159 | E31: 5050 | F31: 11 | G31: 129 | H31: 430 | I31: 64400 | J31: 6 | K31: 4.4 | L31: 5.5
A32: 46053 | B32: SB-031 | C32: Delhi-Mumbai | D32: 161 | E32: 5800 | F32: 10 | G32: 135 | H32: 437 | I32: 51700 | J32: 4 | K32: 4 | L32: 6.8
A33: 46054 | B33: SB-032 | C33: Delhi-Goa | D33: 147 | E33: 6300 | F33: 12 | G33: 166 | H33: 533 | I33: 68400 | J33: 2 | K33: 3.7 | L33: 4.2
A34: 46055 | B34: SB-033 | C34: Delhi-Goa | D34: 169 | E34: 5600 | F34: 24 | G34: 166 | H34: 569 | I34: 64800 | J34: 1 | K34: 4.5 | L34: 3.9
A35: 46056 | B35: SB-034 | C35: Delhi-Bengaluru | D35: 169 | E35: 5450 | F35: 26 | G35: 167 | H35: 548 | I35: 71400 | J35: 8 | K35: 3.9 | L35: 5.6
A36: 46057 | B36: SB-035 | C36: Delhi-Mumbai | D36: 157 | E36: 4800 | F36: 39 | G36: 129 | H36: 425 | I36: 54400 | J36: 4 | K36: 4.1 | L36: 7.7
A37: 46058 | B37: SB-036 | C37: Delhi-Goa | D37: 150 | E37: 5850 | F37: 8 | G37: 169 | H37: 550 | I37: 58000 | J37: 5 | K37: 4 | L37: 6.1
A38: 46059 | B38: SB-037 | C38: Delhi-Bengaluru | D38: 160 | E38: 6600 | F38: 6 | G38: 173 | H38: 590 | I38: 64300 | J38: 3 | K38: 4 | L38: 7.9
A39: 46060 | B39: SB-038 | C39: Delhi-Bengaluru | D39: 215 | E39: 6800 | F39: 5 | G39: 169 | H39: 573 | I39: 51500 | J39: 4 | K39: 4.5
A40: 46061 | B40: SB-039 | C40: Delhi-Goa | D40: 155 | E40: 6700 | F40: 25 | G40: 165 | H40: 530 | I40: 57700 | J40: 2 | K40: 4 | L40: 6.7
...

Sheet Excel_Stats
A1: Descriptive statistics of Unclean_Data (live Excel formulas)
A2: Outlier rule: below Q1 - 1.5 x IQR or above Q3 + 1.5 x IQR. Blank cells are ignored by Excel functions.
A4: Variable | B4: Count | C4: Missing | D4: Mean | E4: Median | F4: Std Dev | G4: Min | H4: Q1 | I4: Q3 | J4: Max | K4: IQR | L4: Lower Fence | M4: Upper Fence | N4: # Outliers
A5: Passengers | B5: =COUNT(Unclean_Data!$D$2:$D$121) -> 115 | C5: =COUNTBLANK(Unclean_Data!$D$2:$D$121) -> 5 | D5: =AVERAGE(Unclean_Data!$D$2:$D$121) -> 154.95652 | E5: =MEDIAN(Unclean_Data!$D$2:$D$121) -> 155 | F5: =STDEV(Unclean_Data!$D$2:$D$121) -> 13.612682 | G5: =MIN(Unclean_Data!$D$2:$D$121) -> 120 | H5: =QUARTILE(Unclean_Data!$D$2:$D$121,1) -> 147 | I5: =QUARTILE(Unclean_Data!$D$2:$D$121,3) -> 163 | J5: =MAX(Unclean_Data!$D$2:$D$121) -> 215 | K5: =I5-H5 -> 16 | L5: =H5-1.5*K5 -> 123 | M5: =I5+1.5*K5 -> 187 | N5: =COUNTIF(Unclean_Data!$D$2:$D$121,"<"&L5)+COUNTIF(Unclean_Data!$D$2:$D$121,">"&M5) -> 2
A6: Ticket_Price | B6: =COUNT(Unclean_Data!$E$2:$E$121) -> 113 | C6: =COUNTBLANK(Unclean_Data!$E$2:$E$121) -> 7 | D6: =AVERAGE(Unclean_Data!$E$2:$E$121) -> 6374.3363 | E6: =MEDIAN(Unclean_Data!$E$2:$E$121) -> 5900 | F6: =STDEV(Unclean_Data!$E$2:$E$121) -> 4836.7091 | G6: =MIN(Unclean_Data!$E$2:$E$121) -> 4800 | H6: =QUARTILE(Unclean_Data!$E$2:$E$121,1) -> 5550 | I6: =QUARTILE(Unclean_Data!$E$2:$E$121,3) -> 6300 | J6: =MAX(Unclean_Data!$E$2:$E$121) -> 57000 | K6: =I6-H6 -> 750 | L6: =H6-1.5*K6 -> 4425 | M6: =I6+1.5*K6 -> 7425 | N6: =COUNTIF(Unclean_Data!$E$2:$E$121,"<"&L6)+COUNTIF(Unclean_Data!$E$2:$E$121,">"&M6) -> 1
A7: Delay_Minutes | B7: =COUNT(Unclean_Data!$F$2:$F$121) -> 114 | C7: =COUNTBLANK(Unclean_Data!$F$2:$F$121) -> 6 | D7: =AVERAGE(Unclean_Data!$F$2:$F$121) -> 19.394737 | E7: =MEDIAN(Unclean_Data!$F$2:$F$121) -> 16 | F7: =STDEV(Unclean_Data!$F$2:$F$121) -> 35.888376 | G7: =MIN(Unclean_Data!$F$2:$F$121) -> -45 | H7: =QUARTILE(Unclean_Data!$F$2:$F$121,1) -> 9 | I7: =QUARTILE(Unclean_Data!$F$2:$F$121,3) -> 23.75 | J7: =MAX(Unclean_Data!$F$2:$F$121) -> 380 | K7: =I7-H7 -> 14.75 | L7: =H7-1.5*K7 -> -13.125 | M7: =I7+1.5*K7 -> 45.875 | N7: =COUNTIF(Unclean_Data!$F$2:$F$121,"<"&L7)+COUNTIF(Unclean_Data!$F$2:$F$121,">"&M7) -> 2
A8: Flight_Duration_Min | B8: =COUNT(Unclean_Data!$G$2:$G$121) -> 116 | C8: =COUNTBLANK(Unclean_Data!$G$2:$G$121) -> 4 | D8: =AVERAGE(Unclean_Data!$G$2:$G$121) -> 157.18966 | E8: =MEDIAN(Unclean_Data!$G$2:$G$121) -> 165 | F8: =STDEV(Unclean_Data!$G$2:$G$121) -> 30.011567 | G8: =MIN(Unclean_Data!$G$2:$G$121) -> 122 | H8: =QUARTILE(Unclean_Data!$G$2:$G$121,1) -> 132 | I8: =QUARTILE(Unclean_Data!$G$2:$G$121,3) -> 170 | J8: =MAX(Unclean_Data!$G$2:$G$121) -> 410 | K8: =I8-H8 -> 38 | L8: =H8-1.5*K8 -> 75 | M8: =I8+1.5*K8 -> 227 | N8: =COUNTIF(Unclean_Data!$G$2:$G$121,"<"&L8)+COUNTIF(Unclean_Data!$G$2:$G$121,">"&M8) -> 1
A9: Fuel_Cost | B9: =COUNT(Unclean_Data!$H$2:$H$121) -> 114 | C9: =COUNTBLANK(Unclean_Data!$H$2:$H$121) -> 6 | D9: =AVERAGE(Unclean_Data!$H$2:$H$121) -> 511.2193 | E9: =MEDIAN(Unclean_Data!$H$2:$H$121) -> 530 | F9: =STDEV(Unclean_Data!$H$2:$H$121) -> 78.027538 | G9: =MIN(Unclean_Data!$H$2:$H$121) -> 398 | H9: =QUARTILE(Unclean_Data!$H$2:$H$121,1) -> 433 | I9: =QUARTILE(Unclean_Data!$H$2:$H$121,3) -> 563.75 | J9: =MAX(Unclean_Data!$H$2:$H$121) -> 980 | K9: =I9-H9 -> 130.75 | L9: =H9-1.5*K9 -> 236.875 | M9: =I9+1.5*K9 -> 759.875 | N9: =COUNTIF(Unclean_Data!$H$2:$H$121,"<"&L9)+COUNTIF(Unclean_Data!$H$2:$H$121,">"&M9) -> 1
A10: Ancillary_Revenue | B10: =COUNT(Unclean_Data!$I$2:$I$121) -> 114 | C10: =COUNTBLANK(Unclean_Data!$I$2:$I$121) -> 6 | D10: =AVERAGE(Unclean_Data!$I$2:$I$121) -> 59615.789 | E10: =MEDIAN(Unclean_Data!$I$2:$I$121) -> 58800 | F10: =STDEV(Unclean_Data!$I$2:$I$121) -> 11182.331 | G10: =MIN(Unclean_Data!$I$2:$I$121) -> 37900 | H10: =QUARTILE(Unclean_Data!$I$2:$I$121,1) -> 54425 | I10: =QUARTILE(Unclean_Data!$I$2:$I$121,3) -> 64225 | J10: =MAX(Unclean_Data!$I$2:$I$121) -> 148000 | K10: =I10-H10 -> 9800 | L10: =H10-1.5*K10 -> 39725 | M10: =I10+1.5*K10 -> 78925 | N10: =COUNTIF(Unclean_Data!$I$2:$I$121,"<"&L10)+COUNTIF(Unclean_Data!$I$2:$I$121,">"&M10) -> 3
A11: Baggage_Complaints | B11: =COUNT(Unclean_Data!$J$2:$J$121) -> 115 | C11: =COUNTBLANK(Unclean_Data!$J$2:$J$121) -> 5 | D11: =AVERAGE(Unclean_Data!$J$2:$J$121) -> 3.1043478 | E11: =MEDIAN(Unclean_Data!$J$2:$J$121) -> 3 | F11: =STDEV(Unclean_Data!$J$2:$J$121) -> 2.4111361 | G11: =MIN(Unclean_Data!$J$2:$J$121) -> 0 | H11: =QUARTILE(Unclean_Data!$J$2:$J$121,1) -> 2 | I11: =QUARTILE(Unclean_Data!$J$2:$J$121,3) -> 4 | J11: =MAX(Unclean_Data!$J$2:$J$121) -> 19 | K11: =I11-H11 -> 2 | L11: =H11-1.5*K11 -> -1 | M11: =I11+1.5*K11 -> 7 | N11: =COUNTIF(Unclean_Data!$J$2:$J$121,"<"&L11)+COUNTIF(Unclean_Data!$J$2:$J$121,">"&M11) -> 6
A12: Customer_Rating | B12: =COUNT(Unclean_Data!$K$2:$K$121) -> 113 | C12: =COUNTBLANK(Unclean_Data!$K$2:$K$121) -> 7 | D12: =AVERAGE(Unclean_Data!$K$2:$K$121) -> 4.1743363 | E12: =MEDIAN(Unclean_Data!$K$2:$K$121) -> 4.1 | F12: =STDEV(Unclean_Data!$K$2:$K$121) -> 0.55818244 | G12: =MIN(Unclean_Data!$K$2:$K$121) -> 3.5 | H12: =QUARTILE(Unclean_Data!$K$2:$K$121,1) -> 4 | I12: =QUARTILE(Unclean_Data!$K$2:$K$121,3) -> 4.3 | J12: =MAX(Unclean_Data!$K$2:$K$121) -> 9.4 | K12: =I12-H12 -> 0.3 | L12: =H12-1.5*K12 -> 3.55 | M12: =I12+1.5*K12 -> 4.75 | N12: =COUNTIF(Unclean_Data!$K$2:$K$121,"<"&L12)+COUNTIF(Unclean_Data!$K$2:$K$121,">"&M12) -> 2
A13: Crew_Overtime_Hours | B13: =COUNT(Unclean_Data!$L$2:$L$121) -> 112 | C13: =COUNTBLANK(Unclean_Data!$L$2:$L$121) -> 8 | D13: =AVERAGE(Unclean_Data!$L$2:$L$121) -> 6.4785714 | E13: =MEDIAN(Unclean_Data!$L$2:$L$121) -> 6.1 | F13: =STDEV(Unclean_Data!$L$2:$L$121) -> 2.8053818 | G13: =MIN(Unclean_Data!$L$2:$L$121) -> 2.8 | H13: =QUARTILE(Unclean_Data!$L$2:$L$121,1) -> 5.2 | I13: =QUARTILE(Unclean_Data!$L$2:$L$121,3) -> 7.3 | J13: =MAX(Unclean_Data!$L$2:$L$121) -> 31.5 | K13: =I13-H13 -> 2.1 | L13: =H13-1.5*K13 -> 2.05 | M13: =I13+1.5*K13 -> 10.45 | N13: =COUNTIF(Unclean_Data!$L$2:$L$121,"<"&L13)+COUNTIF(Unclean_Data!$L$2:$L$121,">"&M13) -> 1
